2023-06-22T05:30:26 {"block_run_id": 184, "block_uuid": "export_weather_postgresql", "pipeline_run_id": 61, "pipeline_schedule_id": 2, "pipeline_uuid": "weather_scraping", "block_type": "data_exporter", "level": "INFO", "message": "Start executing block with BlockExecutor.", "timestamp": 1687411826.078173, "uuid": "fb43b98fb301424fa033048888abaca9"}
2023-06-22T05:30:26 {"block_run_id": 184, "block_uuid": "export_weather_postgresql", "pipeline_run_id": 61, "pipeline_schedule_id": 2, "pipeline_uuid": "weather_scraping", "block_type": "data_exporter", "level": "LOG", "message": "Postgres initialized", "timestamp": 1687411826.27805, "uuid": "846ceaa4f9fa431e96b9efde2a42c585"}
2023-06-22T05:30:26 {"block_run_id": 184, "block_uuid": "export_weather_postgresql", "pipeline_run_id": 61, "pipeline_schedule_id": 2, "pipeline_uuid": "weather_scraping", "block_type": "data_exporter", "level": "LOG", "message": "\u2514\u2500 Opening connection to PostgreSQL database...", "timestamp": 1687411826.279723, "uuid": "7fe5d103eb61456bbf3e17e6a9afad9a"}
2023-06-22T05:30:27 {"block_run_id": 184, "block_uuid": "export_weather_postgresql", "pipeline_run_id": 61, "pipeline_schedule_id": 2, "pipeline_uuid": "weather_scraping", "block_type": "data_exporter", "level": "LOG", "message": "DONE", "timestamp": 1687411827.674291, "uuid": "e796aef91d344d7bb96a3abe82cd9a30"}
2023-06-22T05:30:27 {"block_run_id": 184, "block_uuid": "export_weather_postgresql", "pipeline_run_id": 61, "pipeline_schedule_id": 2, "pipeline_uuid": "weather_scraping", "block_type": "data_exporter", "level": "LOG", "message": "", "timestamp": 1687411827.703428, "uuid": "eab2cd5167ee4833962fa6061d9c1c01"}
2023-06-22T05:30:27 {"block_run_id": 184, "block_uuid": "export_weather_postgresql", "pipeline_run_id": 61, "pipeline_schedule_id": 2, "pipeline_uuid": "weather_scraping", "block_type": "data_exporter", "level": "LOG", "message": "", "timestamp": 1687411827.705149, "uuid": "a0e4f9e023854b988f80f90cf65133db"}
2023-06-22T05:30:27 {"block_run_id": 184, "block_uuid": "export_weather_postgresql", "pipeline_run_id": 61, "pipeline_schedule_id": 2, "pipeline_uuid": "weather_scraping", "block_type": "data_exporter", "level": "LOG", "message": "Exporting data from upstream block transform_weather to public.weather_scraping_transform_weather_v1.", "timestamp": 1687411827.706607, "uuid": "6706192c49ce4023b60f38f40df5c86c"}
2023-06-22T05:30:28 {"block_run_id": 184, "block_uuid": "export_weather_postgresql", "pipeline_run_id": 61, "pipeline_schedule_id": 2, "pipeline_uuid": "weather_scraping", "block_type": "data_exporter", "level": "LOG", "message": "", "timestamp": 1687411828.810933, "uuid": "2b7e1bb53fa6420b8517eab682a6ca60"}
2023-06-22T05:30:28 {"block_run_id": 184, "block_uuid": "export_weather_postgresql", "pipeline_run_id": 61, "pipeline_schedule_id": 2, "pipeline_uuid": "weather_scraping", "block_type": "data_exporter", "level": "LOG", "message": "\u251c\u2500", "timestamp": 1687411828.815925, "uuid": "0e548b9f13d64167b5a346e4e0dfae71"}
2023-06-22T05:30:28 {"block_run_id": 184, "block_uuid": "export_weather_postgresql", "pipeline_run_id": 61, "pipeline_schedule_id": 2, "pipeline_uuid": "weather_scraping", "block_type": "data_exporter", "level": "LOG", "message": "\u2514\u2500 Exporting data to 'public.weather'...", "timestamp": 1687411828.82163, "uuid": "4ac5b50501934eff88ceb06df357ce2e"}
2023-06-22T05:30:29 {"block_run_id": 184, "block_uuid": "export_weather_postgresql", "pipeline_run_id": 61, "pipeline_schedule_id": 2, "pipeline_uuid": "weather_scraping", "block_type": "data_exporter", "level": "LOG", "message": "DONE", "timestamp": 1687411829.485161, "uuid": "ed0fb0e2a1c54dbb95ae2f8698f26b09"}
2023-06-22T05:30:29 {"block_run_id": 184, "block_uuid": "export_weather_postgresql", "pipeline_run_id": 61, "pipeline_schedule_id": 2, "pipeline_uuid": "weather_scraping", "block_type": "data_exporter", "level": "LOG", "message": "", "timestamp": 1687411829.488437, "uuid": "276f6a35c2094bb0b122bb598f2cfeb7"}
2023-06-22T05:30:29 {"block_run_id": 184, "block_uuid": "export_weather_postgresql", "pipeline_run_id": 61, "pipeline_schedule_id": 2, "pipeline_uuid": "weather_scraping", "block_type": "data_exporter", "level": "LOG", "message": "\u251c\u2500", "timestamp": 1687411829.489986, "uuid": "5c377d0281264a99a235456787afce11"}
2023-06-22T05:30:29 {"block_run_id": 184, "block_uuid": "export_weather_postgresql", "pipeline_run_id": 61, "pipeline_schedule_id": 2, "pipeline_uuid": "weather_scraping", "block_type": "data_exporter", "level": "LOG", "message": "\u2514\u2500 Loading data...", "timestamp": 1687411829.492046, "uuid": "3447e8d6a6f94ac4a6bb8379fffb5ba7"}
2023-06-22T05:30:29 {"block_run_id": 184, "block_uuid": "export_weather_postgresql", "pipeline_run_id": 61, "pipeline_schedule_id": 2, "pipeline_uuid": "weather_scraping", "block_type": "data_exporter", "level": "EXCEPTION", "message": "Exception thrown when attempting to run <function BlockExecutor.execute.<locals>.__execute_with_retry at 0xffff57ac5e10>, attempt 1 of 1", "timestamp": 1687411829.62137, "uuid": "9dad212217e14c798452ff3c3d6c67b5", "error": ["Traceback (most recent call last):\n  File \"/usr/local/lib/python3.10/site-packages/pandas/io/sql.py\", line 2018, in execute\n    cur.execute(*args, **kwargs)\npsycopg2.OperationalError: SSL SYSCALL error: EOF detected\n\n\nDuring handling of the above exception, another exception occurred:\n\nTraceback (most recent call last):\n  File \"/usr/local/lib/python3.10/site-packages/pandas/io/sql.py\", line 2022, in execute\n    self.con.rollback()\npsycopg2.InterfaceError: connection already closed\n\nThe above exception was the direct cause of the following exception:\n\nTraceback (most recent call last):\n  File \"/usr/local/lib/python3.10/site-packages/mage_ai/shared/retry.py\", line 34, in retry_func\n    return func(*args, **kwargs)\n  File \"/usr/local/lib/python3.10/site-packages/mage_ai/data_preparation/executors/block_executor.py\", line 84, in __execute_with_retry\n    return self._execute(\n  File \"/usr/local/lib/python3.10/site-packages/mage_ai/data_preparation/executors/block_executor.py\", line 175, in _execute\n    result = self.block.execute_sync(\n  File \"/usr/local/lib/python3.10/site-packages/mage_ai/data_preparation/models/block/__init__.py\", line 801, in execute_sync\n    raise err\n  File \"/usr/local/lib/python3.10/site-packages/mage_ai/data_preparation/models/block/__init__.py\", line 740, in execute_sync\n    output = self.execute_block(\n  File \"/usr/local/lib/python3.10/site-packages/mage_ai/data_preparation/models/block/__init__.py\", line 974, in execute_block\n    outputs = self._execute_block(\n  File \"/usr/local/lib/python3.10/site-packages/mage_ai/data_preparation/models/block/sql/__init__.py\", line 639, in _execute_block\n    return execute_sql_code(\n  File \"/usr/local/lib/python3.10/site-packages/mage_ai/data_preparation/models/block/sql/__init__.py\", line 369, in execute_sql_code\n    loader.load(\n  File \"/usr/local/lib/python3.10/site-packages/mage_ai/io/sql.py\", line 188, in load\n    return read_sql(\n  File \"/usr/local/lib/python3.10/site-packages/pandas/io/sql.py\", line 564, in read_sql\n    return pandas_sql.read_query(\n  File \"/usr/local/lib/python3.10/site-packages/pandas/io/sql.py\", line 2078, in read_query\n    cursor = self.execute(*args)\n  File \"/usr/local/lib/python3.10/site-packages/pandas/io/sql.py\", line 2027, in execute\n    raise ex from inner_exc\npandas.errors.DatabaseError: Execution failed on sql: \nWITH subquery AS (\n    SELECT * FROM public.weather\n)\n\nSELECT *\nFROM subquery\nLIMIT 10000000\n\nSSL SYSCALL error: EOF detected\n\nunable to rollback\n"], "error_stack": [["  File \"/usr/local/bin/mage\", line 8, in <module>\n    sys.exit(app())\n", "  File \"/usr/local/lib/python3.10/site-packages/typer/main.py\", line 311, in __call__\n    return get_command(self)(*args, **kwargs)\n", "  File \"/usr/local/lib/python3.10/site-packages/click/core.py\", line 1130, in __call__\n    return self.main(*args, **kwargs)\n", "  File \"/usr/local/lib/python3.10/site-packages/typer/core.py\", line 778, in main\n    return _main(\n", "  File \"/usr/local/lib/python3.10/site-packages/typer/core.py\", line 216, in _main\n    rv = self.invoke(ctx)\n", "  File \"/usr/local/lib/python3.10/site-packages/click/core.py\", line 1657, in invoke\n    return _process_result(sub_ctx.command.invoke(sub_ctx))\n", "  File \"/usr/local/lib/python3.10/site-packages/click/core.py\", line 1404, in invoke\n    return ctx.invoke(self.callback, **ctx.params)\n", "  File \"/usr/local/lib/python3.10/site-packages/click/core.py\", line 760, in invoke\n    return __callback(*args, **kwargs)\n", "  File \"/usr/local/lib/python3.10/site-packages/typer/main.py\", line 683, in wrapper\n    return callback(**use_params)  # type: ignore\n", "  File \"/usr/local/lib/python3.10/site-packages/mage_ai/cli/main.py\", line 124, in start\n    start_server(\n", "  File \"/usr/local/lib/python3.10/site-packages/mage_ai/server/server.py\", line 316, in start_server\n    scheduler_manager.start_scheduler()\n", "  File \"/usr/local/lib/python3.10/site-packages/mage_ai/server/scheduler_manager.py\", line 70, in start_scheduler\n    proc.start()\n", "  File \"/usr/local/lib/python3.10/multiprocessing/process.py\", line 121, in start\n    self._popen = self._Popen(self)\n", "  File \"/usr/local/lib/python3.10/multiprocessing/context.py\", line 224, in _Popen\n    return _default_context.get_context().Process._Popen(process_obj)\n", "  File \"/usr/local/lib/python3.10/multiprocessing/context.py\", line 281, in _Popen\n    return Popen(process_obj)\n", "  File \"/usr/local/lib/python3.10/multiprocessing/popen_fork.py\", line 19, in __init__\n    self._launch(process_obj)\n", "  File \"/usr/local/lib/python3.10/multiprocessing/popen_fork.py\", line 71, in _launch\n    code = process_obj._bootstrap(parent_sentinel=child_r)\n", "  File \"/usr/local/lib/python3.10/multiprocessing/process.py\", line 314, in _bootstrap\n    self.run()\n", "  File \"/usr/local/lib/python3.10/multiprocessing/process.py\", line 108, in run\n    self._target(*self._args, **self._kwargs)\n", "  File \"/usr/local/lib/python3.10/site-packages/mage_ai/orchestration/db/process.py\", line 15, in start_session_and_run\n    results = target(*args)\n", "  File \"/usr/local/lib/python3.10/site-packages/mage_ai/server/scheduler_manager.py\", line 33, in run_scheduler\n    LoopTimeTrigger().start()\n", "  File \"/usr/local/lib/python3.10/site-packages/mage_ai/orchestration/triggers/loop_time_trigger.py\", line 9, in start\n    self.run()\n", "  File \"/usr/local/lib/python3.10/site-packages/mage_ai/orchestration/triggers/time_trigger.py\", line 10, in run\n    schedule_all()\n", "  File \"/usr/local/lib/python3.10/site-packages/mage_ai/orchestration/pipeline_scheduler.py\", line 1146, in schedule_all\n    PipelineScheduler(r).schedule()\n", "  File \"/usr/local/lib/python3.10/site-packages/mage_ai/orchestration/pipeline_scheduler.py\", line 194, in schedule\n    self.__schedule_blocks(block_runs)\n", "  File \"/usr/local/lib/python3.10/site-packages/mage_ai/orchestration/pipeline_scheduler.py\", line 432, in __schedule_blocks\n    job_manager.add_job(\n", "  File \"/usr/local/lib/python3.10/site-packages/mage_ai/orchestration/job_manager.py\", line 26, in add_job\n    self.queue.enqueue(job_id, target, *args, **kwargs)\n", "  File \"/usr/local/lib/python3.10/site-packages/mage_ai/orchestration/queue/process_queue.py\", line 47, in enqueue\n    self.start_worker_pool()\n", "  File \"/usr/local/lib/python3.10/site-packages/mage_ai/orchestration/queue/process_queue.py\", line 73, in start_worker_pool\n    self.worker_pool_proc.start()\n", "  File \"/usr/local/lib/python3.10/multiprocessing/process.py\", line 121, in start\n    self._popen = self._Popen(self)\n", "  File \"/usr/local/lib/python3.10/multiprocessing/context.py\", line 224, in _Popen\n    return _default_context.get_context().Process._Popen(process_obj)\n", "  File \"/usr/local/lib/python3.10/multiprocessing/context.py\", line 281, in _Popen\n    return Popen(process_obj)\n", "  File \"/usr/local/lib/python3.10/multiprocessing/popen_fork.py\", line 19, in __init__\n    self._launch(process_obj)\n", "  File \"/usr/local/lib/python3.10/multiprocessing/popen_fork.py\", line 71, in _launch\n    code = process_obj._bootstrap(parent_sentinel=child_r)\n", "  File \"/usr/local/lib/python3.10/multiprocessing/process.py\", line 314, in _bootstrap\n    self.run()\n", "  File \"/usr/local/lib/python3.10/multiprocessing/process.py\", line 108, in run\n    self._target(*self._args, **self._kwargs)\n", "  File \"/usr/local/lib/python3.10/site-packages/mage_ai/orchestration/queue/process_queue.py\", line 123, in poll_job_and_execute\n    worker.start()\n", "  File \"/usr/local/lib/python3.10/multiprocessing/process.py\", line 121, in start\n    self._popen = self._Popen(self)\n", "  File \"/usr/local/lib/python3.10/multiprocessing/context.py\", line 224, in _Popen\n    return _default_context.get_context().Process._Popen(process_obj)\n", "  File \"/usr/local/lib/python3.10/multiprocessing/context.py\", line 281, in _Popen\n    return Popen(process_obj)\n", "  File \"/usr/local/lib/python3.10/multiprocessing/popen_fork.py\", line 19, in __init__\n    self._launch(process_obj)\n", "  File \"/usr/local/lib/python3.10/multiprocessing/popen_fork.py\", line 71, in _launch\n    code = process_obj._bootstrap(parent_sentinel=child_r)\n", "  File \"/usr/local/lib/python3.10/multiprocessing/process.py\", line 314, in _bootstrap\n    self.run()\n", "  File \"/usr/local/lib/python3.10/site-packages/mage_ai/orchestration/queue/process_queue.py\", line 103, in run\n    start_session_and_run(args[1], *args[2], **args[3])\n", "  File \"/usr/local/lib/python3.10/site-packages/mage_ai/orchestration/db/process.py\", line 15, in start_session_and_run\n    results = target(*args)\n", "  File \"/usr/local/lib/python3.10/site-packages/mage_ai/orchestration/pipeline_scheduler.py\", line 860, in run_block\n    return ExecutorFactory.get_block_executor(\n", "  File \"/usr/local/lib/python3.10/site-packages/mage_ai/data_preparation/executors/block_executor.py\", line 100, in execute\n    result = __execute_with_retry()\n", "  File \"/usr/local/lib/python3.10/site-packages/mage_ai/shared/retry.py\", line 42, in retry_func\n    logger.exception(\n", "  File \"/usr/local/lib/python3.10/site-packages/mage_ai/data_preparation/logging/logger.py\", line 26, in exception\n    self.__send_message('exception', message, **kwargs)\n", "  File \"/usr/local/lib/python3.10/site-packages/mage_ai/data_preparation/logging/logger.py\", line 55, in __send_message\n    data['error_stack'] = traceback.format_stack(),\n"]], "error_stacktrace": ["Execution failed on sql: \nWITH subquery AS (\n    SELECT * FROM public.weather\n)\n\nSELECT *\nFROM subquery\nLIMIT 10000000\n\nSSL SYSCALL error: EOF detected\n\nunable to rollback"]}
Traceback (most recent call last):
  File "/usr/local/lib/python3.10/site-packages/pandas/io/sql.py", line 2018, in execute
    cur.execute(*args, **kwargs)
psycopg2.OperationalError: SSL SYSCALL error: EOF detected


During handling of the above exception, another exception occurred:

Traceback (most recent call last):
  File "/usr/local/lib/python3.10/site-packages/pandas/io/sql.py", line 2022, in execute
    self.con.rollback()
psycopg2.InterfaceError: connection already closed

The above exception was the direct cause of the following exception:

Traceback (most recent call last):
  File "/usr/local/lib/python3.10/site-packages/mage_ai/shared/retry.py", line 34, in retry_func
    return func(*args, **kwargs)
  File "/usr/local/lib/python3.10/site-packages/mage_ai/data_preparation/executors/block_executor.py", line 84, in __execute_with_retry
    return self._execute(
  File "/usr/local/lib/python3.10/site-packages/mage_ai/data_preparation/executors/block_executor.py", line 175, in _execute
    result = self.block.execute_sync(
  File "/usr/local/lib/python3.10/site-packages/mage_ai/data_preparation/models/block/__init__.py", line 801, in execute_sync
    raise err
  File "/usr/local/lib/python3.10/site-packages/mage_ai/data_preparation/models/block/__init__.py", line 740, in execute_sync
    output = self.execute_block(
  File "/usr/local/lib/python3.10/site-packages/mage_ai/data_preparation/models/block/__init__.py", line 974, in execute_block
    outputs = self._execute_block(
  File "/usr/local/lib/python3.10/site-packages/mage_ai/data_preparation/models/block/sql/__init__.py", line 639, in _execute_block
    return execute_sql_code(
  File "/usr/local/lib/python3.10/site-packages/mage_ai/data_preparation/models/block/sql/__init__.py", line 369, in execute_sql_code
    loader.load(
  File "/usr/local/lib/python3.10/site-packages/mage_ai/io/sql.py", line 188, in load
    return read_sql(
  File "/usr/local/lib/python3.10/site-packages/pandas/io/sql.py", line 564, in read_sql
    return pandas_sql.read_query(
  File "/usr/local/lib/python3.10/site-packages/pandas/io/sql.py", line 2078, in read_query
    cursor = self.execute(*args)
  File "/usr/local/lib/python3.10/site-packages/pandas/io/sql.py", line 2027, in execute
    raise ex from inner_exc
pandas.errors.DatabaseError: Execution failed on sql: 
WITH subquery AS (
    SELECT * FROM public.weather
)

SELECT *
FROM subquery
LIMIT 10000000

SSL SYSCALL error: EOF detected

unable to rollback
2023-06-22T05:30:29 {"block_run_id": 184, "block_uuid": "export_weather_postgresql", "pipeline_run_id": 61, "pipeline_schedule_id": 2, "pipeline_uuid": "weather_scraping", "block_type": "data_exporter", "level": "EXCEPTION", "message": "Failed to execute block export_weather_postgresql", "timestamp": 1687411829.645421, "uuid": "16ae41e44d0741b8b71c5b4f8dc56ae1", "error": ["Traceback (most recent call last):\n  File \"/usr/local/lib/python3.10/site-packages/pandas/io/sql.py\", line 2018, in execute\n    cur.execute(*args, **kwargs)\npsycopg2.OperationalError: SSL SYSCALL error: EOF detected\n\n\nDuring handling of the above exception, another exception occurred:\n\nTraceback (most recent call last):\n  File \"/usr/local/lib/python3.10/site-packages/pandas/io/sql.py\", line 2022, in execute\n    self.con.rollback()\npsycopg2.InterfaceError: connection already closed\n\nThe above exception was the direct cause of the following exception:\n\nTraceback (most recent call last):\n  File \"/usr/local/lib/python3.10/site-packages/mage_ai/data_preparation/executors/block_executor.py\", line 100, in execute\n    result = __execute_with_retry()\n  File \"/usr/local/lib/python3.10/site-packages/mage_ai/shared/retry.py\", line 50, in retry_func\n    raise e\n  File \"/usr/local/lib/python3.10/site-packages/mage_ai/shared/retry.py\", line 34, in retry_func\n    return func(*args, **kwargs)\n  File \"/usr/local/lib/python3.10/site-packages/mage_ai/data_preparation/executors/block_executor.py\", line 84, in __execute_with_retry\n    return self._execute(\n  File \"/usr/local/lib/python3.10/site-packages/mage_ai/data_preparation/executors/block_executor.py\", line 175, in _execute\n    result = self.block.execute_sync(\n  File \"/usr/local/lib/python3.10/site-packages/mage_ai/data_preparation/models/block/__init__.py\", line 801, in execute_sync\n    raise err\n  File \"/usr/local/lib/python3.10/site-packages/mage_ai/data_preparation/models/block/__init__.py\", line 740, in execute_sync\n    output = self.execute_block(\n  File \"/usr/local/lib/python3.10/site-packages/mage_ai/data_preparation/models/block/__init__.py\", line 974, in execute_block\n    outputs = self._execute_block(\n  File \"/usr/local/lib/python3.10/site-packages/mage_ai/data_preparation/models/block/sql/__init__.py\", line 639, in _execute_block\n    return execute_sql_code(\n  File \"/usr/local/lib/python3.10/site-packages/mage_ai/data_preparation/models/block/sql/__init__.py\", line 369, in execute_sql_code\n    loader.load(\n  File \"/usr/local/lib/python3.10/site-packages/mage_ai/io/sql.py\", line 188, in load\n    return read_sql(\n  File \"/usr/local/lib/python3.10/site-packages/pandas/io/sql.py\", line 564, in read_sql\n    return pandas_sql.read_query(\n  File \"/usr/local/lib/python3.10/site-packages/pandas/io/sql.py\", line 2078, in read_query\n    cursor = self.execute(*args)\n  File \"/usr/local/lib/python3.10/site-packages/pandas/io/sql.py\", line 2027, in execute\n    raise ex from inner_exc\npandas.errors.DatabaseError: Execution failed on sql: \nWITH subquery AS (\n    SELECT * FROM public.weather\n)\n\nSELECT *\nFROM subquery\nLIMIT 10000000\n\nSSL SYSCALL error: EOF detected\n\nunable to rollback\n"], "error_stack": [["  File \"/usr/local/bin/mage\", line 8, in <module>\n    sys.exit(app())\n", "  File \"/usr/local/lib/python3.10/site-packages/typer/main.py\", line 311, in __call__\n    return get_command(self)(*args, **kwargs)\n", "  File \"/usr/local/lib/python3.10/site-packages/click/core.py\", line 1130, in __call__\n    return self.main(*args, **kwargs)\n", "  File \"/usr/local/lib/python3.10/site-packages/typer/core.py\", line 778, in main\n    return _main(\n", "  File \"/usr/local/lib/python3.10/site-packages/typer/core.py\", line 216, in _main\n    rv = self.invoke(ctx)\n", "  File \"/usr/local/lib/python3.10/site-packages/click/core.py\", line 1657, in invoke\n    return _process_result(sub_ctx.command.invoke(sub_ctx))\n", "  File \"/usr/local/lib/python3.10/site-packages/click/core.py\", line 1404, in invoke\n    return ctx.invoke(self.callback, **ctx.params)\n", "  File \"/usr/local/lib/python3.10/site-packages/click/core.py\", line 760, in invoke\n    return __callback(*args, **kwargs)\n", "  File \"/usr/local/lib/python3.10/site-packages/typer/main.py\", line 683, in wrapper\n    return callback(**use_params)  # type: ignore\n", "  File \"/usr/local/lib/python3.10/site-packages/mage_ai/cli/main.py\", line 124, in start\n    start_server(\n", "  File \"/usr/local/lib/python3.10/site-packages/mage_ai/server/server.py\", line 316, in start_server\n    scheduler_manager.start_scheduler()\n", "  File \"/usr/local/lib/python3.10/site-packages/mage_ai/server/scheduler_manager.py\", line 70, in start_scheduler\n    proc.start()\n", "  File \"/usr/local/lib/python3.10/multiprocessing/process.py\", line 121, in start\n    self._popen = self._Popen(self)\n", "  File \"/usr/local/lib/python3.10/multiprocessing/context.py\", line 224, in _Popen\n    return _default_context.get_context().Process._Popen(process_obj)\n", "  File \"/usr/local/lib/python3.10/multiprocessing/context.py\", line 281, in _Popen\n    return Popen(process_obj)\n", "  File \"/usr/local/lib/python3.10/multiprocessing/popen_fork.py\", line 19, in __init__\n    self._launch(process_obj)\n", "  File \"/usr/local/lib/python3.10/multiprocessing/popen_fork.py\", line 71, in _launch\n    code = process_obj._bootstrap(parent_sentinel=child_r)\n", "  File \"/usr/local/lib/python3.10/multiprocessing/process.py\", line 314, in _bootstrap\n    self.run()\n", "  File \"/usr/local/lib/python3.10/multiprocessing/process.py\", line 108, in run\n    self._target(*self._args, **self._kwargs)\n", "  File \"/usr/local/lib/python3.10/site-packages/mage_ai/orchestration/db/process.py\", line 15, in start_session_and_run\n    results = target(*args)\n", "  File \"/usr/local/lib/python3.10/site-packages/mage_ai/server/scheduler_manager.py\", line 33, in run_scheduler\n    LoopTimeTrigger().start()\n", "  File \"/usr/local/lib/python3.10/site-packages/mage_ai/orchestration/triggers/loop_time_trigger.py\", line 9, in start\n    self.run()\n", "  File \"/usr/local/lib/python3.10/site-packages/mage_ai/orchestration/triggers/time_trigger.py\", line 10, in run\n    schedule_all()\n", "  File \"/usr/local/lib/python3.10/site-packages/mage_ai/orchestration/pipeline_scheduler.py\", line 1146, in schedule_all\n    PipelineScheduler(r).schedule()\n", "  File \"/usr/local/lib/python3.10/site-packages/mage_ai/orchestration/pipeline_scheduler.py\", line 194, in schedule\n    self.__schedule_blocks(block_runs)\n", "  File \"/usr/local/lib/python3.10/site-packages/mage_ai/orchestration/pipeline_scheduler.py\", line 432, in __schedule_blocks\n    job_manager.add_job(\n", "  File \"/usr/local/lib/python3.10/site-packages/mage_ai/orchestration/job_manager.py\", line 26, in add_job\n    self.queue.enqueue(job_id, target, *args, **kwargs)\n", "  File \"/usr/local/lib/python3.10/site-packages/mage_ai/orchestration/queue/process_queue.py\", line 47, in enqueue\n    self.start_worker_pool()\n", "  File \"/usr/local/lib/python3.10/site-packages/mage_ai/orchestration/queue/process_queue.py\", line 73, in start_worker_pool\n    self.worker_pool_proc.start()\n", "  File \"/usr/local/lib/python3.10/multiprocessing/process.py\", line 121, in start\n    self._popen = self._Popen(self)\n", "  File \"/usr/local/lib/python3.10/multiprocessing/context.py\", line 224, in _Popen\n    return _default_context.get_context().Process._Popen(process_obj)\n", "  File \"/usr/local/lib/python3.10/multiprocessing/context.py\", line 281, in _Popen\n    return Popen(process_obj)\n", "  File \"/usr/local/lib/python3.10/multiprocessing/popen_fork.py\", line 19, in __init__\n    self._launch(process_obj)\n", "  File \"/usr/local/lib/python3.10/multiprocessing/popen_fork.py\", line 71, in _launch\n    code = process_obj._bootstrap(parent_sentinel=child_r)\n", "  File \"/usr/local/lib/python3.10/multiprocessing/process.py\", line 314, in _bootstrap\n    self.run()\n", "  File \"/usr/local/lib/python3.10/multiprocessing/process.py\", line 108, in run\n    self._target(*self._args, **self._kwargs)\n", "  File \"/usr/local/lib/python3.10/site-packages/mage_ai/orchestration/queue/process_queue.py\", line 123, in poll_job_and_execute\n    worker.start()\n", "  File \"/usr/local/lib/python3.10/multiprocessing/process.py\", line 121, in start\n    self._popen = self._Popen(self)\n", "  File \"/usr/local/lib/python3.10/multiprocessing/context.py\", line 224, in _Popen\n    return _default_context.get_context().Process._Popen(process_obj)\n", "  File \"/usr/local/lib/python3.10/multiprocessing/context.py\", line 281, in _Popen\n    return Popen(process_obj)\n", "  File \"/usr/local/lib/python3.10/multiprocessing/popen_fork.py\", line 19, in __init__\n    self._launch(process_obj)\n", "  File \"/usr/local/lib/python3.10/multiprocessing/popen_fork.py\", line 71, in _launch\n    code = process_obj._bootstrap(parent_sentinel=child_r)\n", "  File \"/usr/local/lib/python3.10/multiprocessing/process.py\", line 314, in _bootstrap\n    self.run()\n", "  File \"/usr/local/lib/python3.10/site-packages/mage_ai/orchestration/queue/process_queue.py\", line 103, in run\n    start_session_and_run(args[1], *args[2], **args[3])\n", "  File \"/usr/local/lib/python3.10/site-packages/mage_ai/orchestration/db/process.py\", line 15, in start_session_and_run\n    results = target(*args)\n", "  File \"/usr/local/lib/python3.10/site-packages/mage_ai/orchestration/pipeline_scheduler.py\", line 860, in run_block\n    return ExecutorFactory.get_block_executor(\n", "  File \"/usr/local/lib/python3.10/site-packages/mage_ai/data_preparation/executors/block_executor.py\", line 102, in execute\n    self.logger.exception(\n", "  File \"/usr/local/lib/python3.10/site-packages/mage_ai/data_preparation/logging/logger.py\", line 26, in exception\n    self.__send_message('exception', message, **kwargs)\n", "  File \"/usr/local/lib/python3.10/site-packages/mage_ai/data_preparation/logging/logger.py\", line 55, in __send_message\n    data['error_stack'] = traceback.format_stack(),\n"]], "error_stacktrace": ["Execution failed on sql: \nWITH subquery AS (\n    SELECT * FROM public.weather\n)\n\nSELECT *\nFROM subquery\nLIMIT 10000000\n\nSSL SYSCALL error: EOF detected\n\nunable to rollback"]}
Traceback (most recent call last):
  File "/usr/local/lib/python3.10/site-packages/pandas/io/sql.py", line 2018, in execute
    cur.execute(*args, **kwargs)
psycopg2.OperationalError: SSL SYSCALL error: EOF detected


During handling of the above exception, another exception occurred:

Traceback (most recent call last):
  File "/usr/local/lib/python3.10/site-packages/pandas/io/sql.py", line 2022, in execute
    self.con.rollback()
psycopg2.InterfaceError: connection already closed

The above exception was the direct cause of the following exception:

Traceback (most recent call last):
  File "/usr/local/lib/python3.10/site-packages/mage_ai/data_preparation/executors/block_executor.py", line 100, in execute
    result = __execute_with_retry()
  File "/usr/local/lib/python3.10/site-packages/mage_ai/shared/retry.py", line 50, in retry_func
    raise e
  File "/usr/local/lib/python3.10/site-packages/mage_ai/shared/retry.py", line 34, in retry_func
    return func(*args, **kwargs)
  File "/usr/local/lib/python3.10/site-packages/mage_ai/data_preparation/executors/block_executor.py", line 84, in __execute_with_retry
    return self._execute(
  File "/usr/local/lib/python3.10/site-packages/mage_ai/data_preparation/executors/block_executor.py", line 175, in _execute
    result = self.block.execute_sync(
  File "/usr/local/lib/python3.10/site-packages/mage_ai/data_preparation/models/block/__init__.py", line 801, in execute_sync
    raise err
  File "/usr/local/lib/python3.10/site-packages/mage_ai/data_preparation/models/block/__init__.py", line 740, in execute_sync
    output = self.execute_block(
  File "/usr/local/lib/python3.10/site-packages/mage_ai/data_preparation/models/block/__init__.py", line 974, in execute_block
    outputs = self._execute_block(
  File "/usr/local/lib/python3.10/site-packages/mage_ai/data_preparation/models/block/sql/__init__.py", line 639, in _execute_block
    return execute_sql_code(
  File "/usr/local/lib/python3.10/site-packages/mage_ai/data_preparation/models/block/sql/__init__.py", line 369, in execute_sql_code
    loader.load(
  File "/usr/local/lib/python3.10/site-packages/mage_ai/io/sql.py", line 188, in load
    return read_sql(
  File "/usr/local/lib/python3.10/site-packages/pandas/io/sql.py", line 564, in read_sql
    return pandas_sql.read_query(
  File "/usr/local/lib/python3.10/site-packages/pandas/io/sql.py", line 2078, in read_query
    cursor = self.execute(*args)
  File "/usr/local/lib/python3.10/site-packages/pandas/io/sql.py", line 2027, in execute
    raise ex from inner_exc
pandas.errors.DatabaseError: Execution failed on sql: 
WITH subquery AS (
    SELECT * FROM public.weather
)

SELECT *
FROM subquery
LIMIT 10000000

SSL SYSCALL error: EOF detected

unable to rollback
