2023-07-01T16:19:09 {"block_run_id": 609, "block_uuid": "export_weather_gcp", "pipeline_run_id": 182, "pipeline_schedule_id": 2, "pipeline_uuid": "weather_scraping", "block_type": "data_exporter", "level": "INFO", "message": "Start executing block with BlockExecutor.", "timestamp": 1688228349.571622, "uuid": "cd1405c3be94421f9848df4634a99c56"}
2023-07-01T16:19:09 {"block_run_id": 609, "block_uuid": "export_weather_gcp", "pipeline_run_id": 182, "pipeline_schedule_id": 2, "pipeline_uuid": "weather_scraping", "block_type": "data_exporter", "level": "LOG", "message": "GoogleCloudStorage initialized", "timestamp": 1688228349.609085, "uuid": "375298b4897f452691b6c88c798d4e91"}
2023-07-01T16:19:09 {"block_run_id": 609, "block_uuid": "export_weather_gcp", "pipeline_run_id": 182, "pipeline_schedule_id": 2, "pipeline_uuid": "weather_scraping", "block_type": "data_exporter", "level": "LOG", "message": "\u2514\u2500 Exporting data frame to bucket 'weather_mage' at key 'weather_23-07-01 16:19:09'...", "timestamp": 1688228349.615245, "uuid": "d665aa7fe8cc43e095172a79e0ef8804"}
2023-07-01T17:54:21 {"block_run_id": 609, "block_uuid": "export_weather_gcp", "pipeline_run_id": 182, "pipeline_schedule_id": 2, "pipeline_uuid": "weather_scraping", "block_type": "data_exporter", "level": "EXCEPTION", "message": "Exception thrown when attempting to run <function BlockExecutor.execute.<locals>.__execute_with_retry at 0xffff7d0e3d90>, attempt 1 of 1", "timestamp": 1688234061.816171, "uuid": "2cf4386f8eac49d9952d02de094f3b66", "error": ["Traceback (most recent call last):\n  File \"/usr/local/lib/python3.10/site-packages/urllib3/connectionpool.py\", line 714, in urlopen\n    httplib_response = self._make_request(\n  File \"/usr/local/lib/python3.10/site-packages/urllib3/connectionpool.py\", line 466, in _make_request\n    six.raise_from(e, None)\n  File \"<string>\", line 3, in raise_from\n  File \"/usr/local/lib/python3.10/site-packages/urllib3/connectionpool.py\", line 461, in _make_request\n    httplib_response = conn.getresponse()\n  File \"/usr/local/lib/python3.10/http/client.py\", line 1375, in getresponse\n    response.begin()\n  File \"/usr/local/lib/python3.10/http/client.py\", line 318, in begin\n    version, status, reason = self._read_status()\n  File \"/usr/local/lib/python3.10/http/client.py\", line 287, in _read_status\n    raise RemoteDisconnected(\"Remote end closed connection without\"\nhttp.client.RemoteDisconnected: Remote end closed connection without response\n\nDuring handling of the above exception, another exception occurred:\n\nTraceback (most recent call last):\n  File \"/usr/local/lib/python3.10/site-packages/requests/adapters.py\", line 440, in send\n    resp = conn.urlopen(\n  File \"/usr/local/lib/python3.10/site-packages/urllib3/connectionpool.py\", line 798, in urlopen\n    retries = retries.increment(\n  File \"/usr/local/lib/python3.10/site-packages/urllib3/util/retry.py\", line 550, in increment\n    raise six.reraise(type(error), error, _stacktrace)\n  File \"/usr/local/lib/python3.10/site-packages/urllib3/packages/six.py\", line 769, in reraise\n    raise value.with_traceback(tb)\n  File \"/usr/local/lib/python3.10/site-packages/urllib3/connectionpool.py\", line 714, in urlopen\n    httplib_response = self._make_request(\n  File \"/usr/local/lib/python3.10/site-packages/urllib3/connectionpool.py\", line 466, in _make_request\n    six.raise_from(e, None)\n  File \"<string>\", line 3, in raise_from\n  File \"/usr/local/lib/python3.10/site-packages/urllib3/connectionpool.py\", line 461, in _make_request\n    httplib_response = conn.getresponse()\n  File \"/usr/local/lib/python3.10/http/client.py\", line 1375, in getresponse\n    response.begin()\n  File \"/usr/local/lib/python3.10/http/client.py\", line 318, in begin\n    version, status, reason = self._read_status()\n  File \"/usr/local/lib/python3.10/http/client.py\", line 287, in _read_status\n    raise RemoteDisconnected(\"Remote end closed connection without\"\nurllib3.exceptions.ProtocolError: ('Connection aborted.', RemoteDisconnected('Remote end closed connection without response'))\n\nDuring handling of the above exception, another exception occurred:\n\nTraceback (most recent call last):\n  File \"/usr/local/lib/python3.10/site-packages/mage_ai/shared/retry.py\", line 34, in retry_func\n    return func(*args, **kwargs)\n  File \"/usr/local/lib/python3.10/site-packages/mage_ai/data_preparation/executors/block_executor.py\", line 84, in __execute_with_retry\n    return self._execute(\n  File \"/usr/local/lib/python3.10/site-packages/mage_ai/data_preparation/executors/block_executor.py\", line 175, in _execute\n    result = self.block.execute_sync(\n  File \"/usr/local/lib/python3.10/site-packages/mage_ai/data_preparation/models/block/__init__.py\", line 801, in execute_sync\n    raise err\n  File \"/usr/local/lib/python3.10/site-packages/mage_ai/data_preparation/models/block/__init__.py\", line 740, in execute_sync\n    output = self.execute_block(\n  File \"/usr/local/lib/python3.10/site-packages/mage_ai/data_preparation/models/block/__init__.py\", line 974, in execute_block\n    outputs = self._execute_block(\n  File \"/usr/local/lib/python3.10/site-packages/mage_ai/data_preparation/models/block/__init__.py\", line 1049, in _execute_block\n    outputs = self.execute_block_function(\n  File \"/usr/local/lib/python3.10/site-packages/mage_ai/data_preparation/models/block/__init__.py\", line 1075, in execute_block_function\n    output = block_function(*input_vars, **global_vars)\n  File \"<string>\", line 28, in export_data_to_google_cloud_storage\n  File \"/usr/local/lib/python3.10/site-packages/mage_ai/io/google_cloud_storage.py\", line 131, in export\n    blob.upload_from_string(buffer.read())\n  File \"/usr/local/lib/python3.10/site-packages/google/cloud/storage/blob.py\", line 2840, in upload_from_string\n    self.upload_from_file(\n  File \"/usr/local/lib/python3.10/site-packages/google/cloud/storage/blob.py\", line 2567, in upload_from_file\n    created_json = self._do_upload(\n  File \"/usr/local/lib/python3.10/site-packages/google/cloud/storage/blob.py\", line 2368, in _do_upload\n    response = self._do_multipart_upload(\n  File \"/usr/local/lib/python3.10/site-packages/google/cloud/storage/blob.py\", line 1903, in _do_multipart_upload\n    response = upload.transmit(\n  File \"/usr/local/lib/python3.10/site-packages/google/resumable_media/requests/upload.py\", line 153, in transmit\n    return _request_helpers.wait_and_retry(\n  File \"/usr/local/lib/python3.10/site-packages/google/resumable_media/requests/_request_helpers.py\", line 178, in wait_and_retry\n    raise error\n  File \"/usr/local/lib/python3.10/site-packages/google/resumable_media/requests/_request_helpers.py\", line 155, in wait_and_retry\n    response = func()\n  File \"/usr/local/lib/python3.10/site-packages/google/resumable_media/requests/upload.py\", line 145, in retriable_request\n    result = transport.request(\n  File \"/usr/local/lib/python3.10/site-packages/google/auth/transport/requests.py\", line 549, in request\n    response = super(AuthorizedSession, self).request(\n  File \"/usr/local/lib/python3.10/site-packages/requests/sessions.py\", line 529, in request\n    resp = self.send(prep, **send_kwargs)\n  File \"/usr/local/lib/python3.10/site-packages/requests/sessions.py\", line 645, in send\n    r = adapter.send(request, **kwargs)\n  File \"/usr/local/lib/python3.10/site-packages/requests/adapters.py\", line 501, in send\n    raise ConnectionError(err, request=request)\nrequests.exceptions.ConnectionError: ('Connection aborted.', RemoteDisconnected('Remote end closed connection without response'))\n"], "error_stack": [["  File \"/usr/local/bin/mage\", line 8, in <module>\n    sys.exit(app())\n", "  File \"/usr/local/lib/python3.10/site-packages/typer/main.py\", line 311, in __call__\n    return get_command(self)(*args, **kwargs)\n", "  File \"/usr/local/lib/python3.10/site-packages/click/core.py\", line 1130, in __call__\n    return self.main(*args, **kwargs)\n", "  File \"/usr/local/lib/python3.10/site-packages/typer/core.py\", line 778, in main\n    return _main(\n", "  File \"/usr/local/lib/python3.10/site-packages/typer/core.py\", line 216, in _main\n    rv = self.invoke(ctx)\n", "  File \"/usr/local/lib/python3.10/site-packages/click/core.py\", line 1657, in invoke\n    return _process_result(sub_ctx.command.invoke(sub_ctx))\n", "  File \"/usr/local/lib/python3.10/site-packages/click/core.py\", line 1404, in invoke\n    return ctx.invoke(self.callback, **ctx.params)\n", "  File \"/usr/local/lib/python3.10/site-packages/click/core.py\", line 760, in invoke\n    return __callback(*args, **kwargs)\n", "  File \"/usr/local/lib/python3.10/site-packages/typer/main.py\", line 683, in wrapper\n    return callback(**use_params)  # type: ignore\n", "  File \"/usr/local/lib/python3.10/site-packages/mage_ai/cli/main.py\", line 124, in start\n    start_server(\n", "  File \"/usr/local/lib/python3.10/site-packages/mage_ai/server/server.py\", line 316, in start_server\n    scheduler_manager.start_scheduler()\n", "  File \"/usr/local/lib/python3.10/site-packages/mage_ai/server/scheduler_manager.py\", line 70, in start_scheduler\n    proc.start()\n", "  File \"/usr/local/lib/python3.10/multiprocessing/process.py\", line 121, in start\n    self._popen = self._Popen(self)\n", "  File \"/usr/local/lib/python3.10/multiprocessing/context.py\", line 224, in _Popen\n    return _default_context.get_context().Process._Popen(process_obj)\n", "  File \"/usr/local/lib/python3.10/multiprocessing/context.py\", line 281, in _Popen\n    return Popen(process_obj)\n", "  File \"/usr/local/lib/python3.10/multiprocessing/popen_fork.py\", line 19, in __init__\n    self._launch(process_obj)\n", "  File \"/usr/local/lib/python3.10/multiprocessing/popen_fork.py\", line 71, in _launch\n    code = process_obj._bootstrap(parent_sentinel=child_r)\n", "  File \"/usr/local/lib/python3.10/multiprocessing/process.py\", line 314, in _bootstrap\n    self.run()\n", "  File \"/usr/local/lib/python3.10/multiprocessing/process.py\", line 108, in run\n    self._target(*self._args, **self._kwargs)\n", "  File \"/usr/local/lib/python3.10/site-packages/mage_ai/orchestration/db/process.py\", line 15, in start_session_and_run\n    results = target(*args)\n", "  File \"/usr/local/lib/python3.10/site-packages/mage_ai/server/scheduler_manager.py\", line 33, in run_scheduler\n    LoopTimeTrigger().start()\n", "  File \"/usr/local/lib/python3.10/site-packages/mage_ai/orchestration/triggers/loop_time_trigger.py\", line 9, in start\n    self.run()\n", "  File \"/usr/local/lib/python3.10/site-packages/mage_ai/orchestration/triggers/time_trigger.py\", line 10, in run\n    schedule_all()\n", "  File \"/usr/local/lib/python3.10/site-packages/mage_ai/orchestration/pipeline_scheduler.py\", line 1146, in schedule_all\n    PipelineScheduler(r).schedule()\n", "  File \"/usr/local/lib/python3.10/site-packages/mage_ai/orchestration/pipeline_scheduler.py\", line 194, in schedule\n    self.__schedule_blocks(block_runs)\n", "  File \"/usr/local/lib/python3.10/site-packages/mage_ai/orchestration/pipeline_scheduler.py\", line 432, in __schedule_blocks\n    job_manager.add_job(\n", "  File \"/usr/local/lib/python3.10/site-packages/mage_ai/orchestration/job_manager.py\", line 26, in add_job\n    self.queue.enqueue(job_id, target, *args, **kwargs)\n", "  File \"/usr/local/lib/python3.10/site-packages/mage_ai/orchestration/queue/process_queue.py\", line 47, in enqueue\n    self.start_worker_pool()\n", "  File \"/usr/local/lib/python3.10/site-packages/mage_ai/orchestration/queue/process_queue.py\", line 73, in start_worker_pool\n    self.worker_pool_proc.start()\n", "  File \"/usr/local/lib/python3.10/multiprocessing/process.py\", line 121, in start\n    self._popen = self._Popen(self)\n", "  File \"/usr/local/lib/python3.10/multiprocessing/context.py\", line 224, in _Popen\n    return _default_context.get_context().Process._Popen(process_obj)\n", "  File \"/usr/local/lib/python3.10/multiprocessing/context.py\", line 281, in _Popen\n    return Popen(process_obj)\n", "  File \"/usr/local/lib/python3.10/multiprocessing/popen_fork.py\", line 19, in __init__\n    self._launch(process_obj)\n", "  File \"/usr/local/lib/python3.10/multiprocessing/popen_fork.py\", line 71, in _launch\n    code = process_obj._bootstrap(parent_sentinel=child_r)\n", "  File \"/usr/local/lib/python3.10/multiprocessing/process.py\", line 314, in _bootstrap\n    self.run()\n", "  File \"/usr/local/lib/python3.10/multiprocessing/process.py\", line 108, in run\n    self._target(*self._args, **self._kwargs)\n", "  File \"/usr/local/lib/python3.10/site-packages/mage_ai/orchestration/queue/process_queue.py\", line 123, in poll_job_and_execute\n    worker.start()\n", "  File \"/usr/local/lib/python3.10/multiprocessing/process.py\", line 121, in start\n    self._popen = self._Popen(self)\n", "  File \"/usr/local/lib/python3.10/multiprocessing/context.py\", line 224, in _Popen\n    return _default_context.get_context().Process._Popen(process_obj)\n", "  File \"/usr/local/lib/python3.10/multiprocessing/context.py\", line 281, in _Popen\n    return Popen(process_obj)\n", "  File \"/usr/local/lib/python3.10/multiprocessing/popen_fork.py\", line 19, in __init__\n    self._launch(process_obj)\n", "  File \"/usr/local/lib/python3.10/multiprocessing/popen_fork.py\", line 71, in _launch\n    code = process_obj._bootstrap(parent_sentinel=child_r)\n", "  File \"/usr/local/lib/python3.10/multiprocessing/process.py\", line 314, in _bootstrap\n    self.run()\n", "  File \"/usr/local/lib/python3.10/site-packages/mage_ai/orchestration/queue/process_queue.py\", line 103, in run\n    start_session_and_run(args[1], *args[2], **args[3])\n", "  File \"/usr/local/lib/python3.10/site-packages/mage_ai/orchestration/db/process.py\", line 15, in start_session_and_run\n    results = target(*args)\n", "  File \"/usr/local/lib/python3.10/site-packages/mage_ai/orchestration/pipeline_scheduler.py\", line 860, in run_block\n    return ExecutorFactory.get_block_executor(\n", "  File \"/usr/local/lib/python3.10/site-packages/mage_ai/data_preparation/executors/block_executor.py\", line 100, in execute\n    result = __execute_with_retry()\n", "  File \"/usr/local/lib/python3.10/site-packages/mage_ai/shared/retry.py\", line 42, in retry_func\n    logger.exception(\n", "  File \"/usr/local/lib/python3.10/site-packages/mage_ai/data_preparation/logging/logger.py\", line 26, in exception\n    self.__send_message('exception', message, **kwargs)\n", "  File \"/usr/local/lib/python3.10/site-packages/mage_ai/data_preparation/logging/logger.py\", line 55, in __send_message\n    data['error_stack'] = traceback.format_stack(),\n"]], "error_stacktrace": ["('Connection aborted.', RemoteDisconnected('Remote end closed connection without response'))"]}
Traceback (most recent call last):
  File "/usr/local/lib/python3.10/site-packages/urllib3/connectionpool.py", line 714, in urlopen
    httplib_response = self._make_request(
  File "/usr/local/lib/python3.10/site-packages/urllib3/connectionpool.py", line 466, in _make_request
    six.raise_from(e, None)
  File "<string>", line 3, in raise_from
  File "/usr/local/lib/python3.10/site-packages/urllib3/connectionpool.py", line 461, in _make_request
    httplib_response = conn.getresponse()
  File "/usr/local/lib/python3.10/http/client.py", line 1375, in getresponse
    response.begin()
  File "/usr/local/lib/python3.10/http/client.py", line 318, in begin
    version, status, reason = self._read_status()
  File "/usr/local/lib/python3.10/http/client.py", line 287, in _read_status
    raise RemoteDisconnected("Remote end closed connection without"
http.client.RemoteDisconnected: Remote end closed connection without response

During handling of the above exception, another exception occurred:

Traceback (most recent call last):
  File "/usr/local/lib/python3.10/site-packages/requests/adapters.py", line 440, in send
    resp = conn.urlopen(
  File "/usr/local/lib/python3.10/site-packages/urllib3/connectionpool.py", line 798, in urlopen
    retries = retries.increment(
  File "/usr/local/lib/python3.10/site-packages/urllib3/util/retry.py", line 550, in increment
    raise six.reraise(type(error), error, _stacktrace)
  File "/usr/local/lib/python3.10/site-packages/urllib3/packages/six.py", line 769, in reraise
    raise value.with_traceback(tb)
  File "/usr/local/lib/python3.10/site-packages/urllib3/connectionpool.py", line 714, in urlopen
    httplib_response = self._make_request(
  File "/usr/local/lib/python3.10/site-packages/urllib3/connectionpool.py", line 466, in _make_request
    six.raise_from(e, None)
  File "<string>", line 3, in raise_from
  File "/usr/local/lib/python3.10/site-packages/urllib3/connectionpool.py", line 461, in _make_request
    httplib_response = conn.getresponse()
  File "/usr/local/lib/python3.10/http/client.py", line 1375, in getresponse
    response.begin()
  File "/usr/local/lib/python3.10/http/client.py", line 318, in begin
    version, status, reason = self._read_status()
  File "/usr/local/lib/python3.10/http/client.py", line 287, in _read_status
    raise RemoteDisconnected("Remote end closed connection without"
urllib3.exceptions.ProtocolError: ('Connection aborted.', RemoteDisconnected('Remote end closed connection without response'))

During handling of the above exception, another exception occurred:

Traceback (most recent call last):
  File "/usr/local/lib/python3.10/site-packages/mage_ai/shared/retry.py", line 34, in retry_func
    return func(*args, **kwargs)
  File "/usr/local/lib/python3.10/site-packages/mage_ai/data_preparation/executors/block_executor.py", line 84, in __execute_with_retry
    return self._execute(
  File "/usr/local/lib/python3.10/site-packages/mage_ai/data_preparation/executors/block_executor.py", line 175, in _execute
    result = self.block.execute_sync(
  File "/usr/local/lib/python3.10/site-packages/mage_ai/data_preparation/models/block/__init__.py", line 801, in execute_sync
    raise err
  File "/usr/local/lib/python3.10/site-packages/mage_ai/data_preparation/models/block/__init__.py", line 740, in execute_sync
    output = self.execute_block(
  File "/usr/local/lib/python3.10/site-packages/mage_ai/data_preparation/models/block/__init__.py", line 974, in execute_block
    outputs = self._execute_block(
  File "/usr/local/lib/python3.10/site-packages/mage_ai/data_preparation/models/block/__init__.py", line 1049, in _execute_block
    outputs = self.execute_block_function(
  File "/usr/local/lib/python3.10/site-packages/mage_ai/data_preparation/models/block/__init__.py", line 1075, in execute_block_function
    output = block_function(*input_vars, **global_vars)
  File "<string>", line 28, in export_data_to_google_cloud_storage
  File "/usr/local/lib/python3.10/site-packages/mage_ai/io/google_cloud_storage.py", line 131, in export
    blob.upload_from_string(buffer.read())
  File "/usr/local/lib/python3.10/site-packages/google/cloud/storage/blob.py", line 2840, in upload_from_string
    self.upload_from_file(
  File "/usr/local/lib/python3.10/site-packages/google/cloud/storage/blob.py", line 2567, in upload_from_file
    created_json = self._do_upload(
  File "/usr/local/lib/python3.10/site-packages/google/cloud/storage/blob.py", line 2368, in _do_upload
    response = self._do_multipart_upload(
  File "/usr/local/lib/python3.10/site-packages/google/cloud/storage/blob.py", line 1903, in _do_multipart_upload
    response = upload.transmit(
  File "/usr/local/lib/python3.10/site-packages/google/resumable_media/requests/upload.py", line 153, in transmit
    return _request_helpers.wait_and_retry(
  File "/usr/local/lib/python3.10/site-packages/google/resumable_media/requests/_request_helpers.py", line 178, in wait_and_retry
    raise error
  File "/usr/local/lib/python3.10/site-packages/google/resumable_media/requests/_request_helpers.py", line 155, in wait_and_retry
    response = func()
  File "/usr/local/lib/python3.10/site-packages/google/resumable_media/requests/upload.py", line 145, in retriable_request
    result = transport.request(
  File "/usr/local/lib/python3.10/site-packages/google/auth/transport/requests.py", line 549, in request
    response = super(AuthorizedSession, self).request(
  File "/usr/local/lib/python3.10/site-packages/requests/sessions.py", line 529, in request
    resp = self.send(prep, **send_kwargs)
  File "/usr/local/lib/python3.10/site-packages/requests/sessions.py", line 645, in send
    r = adapter.send(request, **kwargs)
  File "/usr/local/lib/python3.10/site-packages/requests/adapters.py", line 501, in send
    raise ConnectionError(err, request=request)
requests.exceptions.ConnectionError: ('Connection aborted.', RemoteDisconnected('Remote end closed connection without response'))
2023-07-01T17:54:21 {"block_run_id": 609, "block_uuid": "export_weather_gcp", "pipeline_run_id": 182, "pipeline_schedule_id": 2, "pipeline_uuid": "weather_scraping", "block_type": "data_exporter", "level": "EXCEPTION", "message": "Failed to execute block export_weather_gcp", "timestamp": 1688234061.83526, "uuid": "587fdfd15e8548b7bcd93f7be26842e3", "error": ["Traceback (most recent call last):\n  File \"/usr/local/lib/python3.10/site-packages/urllib3/connectionpool.py\", line 714, in urlopen\n    httplib_response = self._make_request(\n  File \"/usr/local/lib/python3.10/site-packages/urllib3/connectionpool.py\", line 466, in _make_request\n    six.raise_from(e, None)\n  File \"<string>\", line 3, in raise_from\n  File \"/usr/local/lib/python3.10/site-packages/urllib3/connectionpool.py\", line 461, in _make_request\n    httplib_response = conn.getresponse()\n  File \"/usr/local/lib/python3.10/http/client.py\", line 1375, in getresponse\n    response.begin()\n  File \"/usr/local/lib/python3.10/http/client.py\", line 318, in begin\n    version, status, reason = self._read_status()\n  File \"/usr/local/lib/python3.10/http/client.py\", line 287, in _read_status\n    raise RemoteDisconnected(\"Remote end closed connection without\"\nhttp.client.RemoteDisconnected: Remote end closed connection without response\n\nDuring handling of the above exception, another exception occurred:\n\nTraceback (most recent call last):\n  File \"/usr/local/lib/python3.10/site-packages/requests/adapters.py\", line 440, in send\n    resp = conn.urlopen(\n  File \"/usr/local/lib/python3.10/site-packages/urllib3/connectionpool.py\", line 798, in urlopen\n    retries = retries.increment(\n  File \"/usr/local/lib/python3.10/site-packages/urllib3/util/retry.py\", line 550, in increment\n    raise six.reraise(type(error), error, _stacktrace)\n  File \"/usr/local/lib/python3.10/site-packages/urllib3/packages/six.py\", line 769, in reraise\n    raise value.with_traceback(tb)\n  File \"/usr/local/lib/python3.10/site-packages/urllib3/connectionpool.py\", line 714, in urlopen\n    httplib_response = self._make_request(\n  File \"/usr/local/lib/python3.10/site-packages/urllib3/connectionpool.py\", line 466, in _make_request\n    six.raise_from(e, None)\n  File \"<string>\", line 3, in raise_from\n  File \"/usr/local/lib/python3.10/site-packages/urllib3/connectionpool.py\", line 461, in _make_request\n    httplib_response = conn.getresponse()\n  File \"/usr/local/lib/python3.10/http/client.py\", line 1375, in getresponse\n    response.begin()\n  File \"/usr/local/lib/python3.10/http/client.py\", line 318, in begin\n    version, status, reason = self._read_status()\n  File \"/usr/local/lib/python3.10/http/client.py\", line 287, in _read_status\n    raise RemoteDisconnected(\"Remote end closed connection without\"\nurllib3.exceptions.ProtocolError: ('Connection aborted.', RemoteDisconnected('Remote end closed connection without response'))\n\nDuring handling of the above exception, another exception occurred:\n\nTraceback (most recent call last):\n  File \"/usr/local/lib/python3.10/site-packages/mage_ai/data_preparation/executors/block_executor.py\", line 100, in execute\n    result = __execute_with_retry()\n  File \"/usr/local/lib/python3.10/site-packages/mage_ai/shared/retry.py\", line 50, in retry_func\n    raise e\n  File \"/usr/local/lib/python3.10/site-packages/mage_ai/shared/retry.py\", line 34, in retry_func\n    return func(*args, **kwargs)\n  File \"/usr/local/lib/python3.10/site-packages/mage_ai/data_preparation/executors/block_executor.py\", line 84, in __execute_with_retry\n    return self._execute(\n  File \"/usr/local/lib/python3.10/site-packages/mage_ai/data_preparation/executors/block_executor.py\", line 175, in _execute\n    result = self.block.execute_sync(\n  File \"/usr/local/lib/python3.10/site-packages/mage_ai/data_preparation/models/block/__init__.py\", line 801, in execute_sync\n    raise err\n  File \"/usr/local/lib/python3.10/site-packages/mage_ai/data_preparation/models/block/__init__.py\", line 740, in execute_sync\n    output = self.execute_block(\n  File \"/usr/local/lib/python3.10/site-packages/mage_ai/data_preparation/models/block/__init__.py\", line 974, in execute_block\n    outputs = self._execute_block(\n  File \"/usr/local/lib/python3.10/site-packages/mage_ai/data_preparation/models/block/__init__.py\", line 1049, in _execute_block\n    outputs = self.execute_block_function(\n  File \"/usr/local/lib/python3.10/site-packages/mage_ai/data_preparation/models/block/__init__.py\", line 1075, in execute_block_function\n    output = block_function(*input_vars, **global_vars)\n  File \"<string>\", line 28, in export_data_to_google_cloud_storage\n  File \"/usr/local/lib/python3.10/site-packages/mage_ai/io/google_cloud_storage.py\", line 131, in export\n    blob.upload_from_string(buffer.read())\n  File \"/usr/local/lib/python3.10/site-packages/google/cloud/storage/blob.py\", line 2840, in upload_from_string\n    self.upload_from_file(\n  File \"/usr/local/lib/python3.10/site-packages/google/cloud/storage/blob.py\", line 2567, in upload_from_file\n    created_json = self._do_upload(\n  File \"/usr/local/lib/python3.10/site-packages/google/cloud/storage/blob.py\", line 2368, in _do_upload\n    response = self._do_multipart_upload(\n  File \"/usr/local/lib/python3.10/site-packages/google/cloud/storage/blob.py\", line 1903, in _do_multipart_upload\n    response = upload.transmit(\n  File \"/usr/local/lib/python3.10/site-packages/google/resumable_media/requests/upload.py\", line 153, in transmit\n    return _request_helpers.wait_and_retry(\n  File \"/usr/local/lib/python3.10/site-packages/google/resumable_media/requests/_request_helpers.py\", line 178, in wait_and_retry\n    raise error\n  File \"/usr/local/lib/python3.10/site-packages/google/resumable_media/requests/_request_helpers.py\", line 155, in wait_and_retry\n    response = func()\n  File \"/usr/local/lib/python3.10/site-packages/google/resumable_media/requests/upload.py\", line 145, in retriable_request\n    result = transport.request(\n  File \"/usr/local/lib/python3.10/site-packages/google/auth/transport/requests.py\", line 549, in request\n    response = super(AuthorizedSession, self).request(\n  File \"/usr/local/lib/python3.10/site-packages/requests/sessions.py\", line 529, in request\n    resp = self.send(prep, **send_kwargs)\n  File \"/usr/local/lib/python3.10/site-packages/requests/sessions.py\", line 645, in send\n    r = adapter.send(request, **kwargs)\n  File \"/usr/local/lib/python3.10/site-packages/requests/adapters.py\", line 501, in send\n    raise ConnectionError(err, request=request)\nrequests.exceptions.ConnectionError: ('Connection aborted.', RemoteDisconnected('Remote end closed connection without response'))\n"], "error_stack": [["  File \"/usr/local/bin/mage\", line 8, in <module>\n    sys.exit(app())\n", "  File \"/usr/local/lib/python3.10/site-packages/typer/main.py\", line 311, in __call__\n    return get_command(self)(*args, **kwargs)\n", "  File \"/usr/local/lib/python3.10/site-packages/click/core.py\", line 1130, in __call__\n    return self.main(*args, **kwargs)\n", "  File \"/usr/local/lib/python3.10/site-packages/typer/core.py\", line 778, in main\n    return _main(\n", "  File \"/usr/local/lib/python3.10/site-packages/typer/core.py\", line 216, in _main\n    rv = self.invoke(ctx)\n", "  File \"/usr/local/lib/python3.10/site-packages/click/core.py\", line 1657, in invoke\n    return _process_result(sub_ctx.command.invoke(sub_ctx))\n", "  File \"/usr/local/lib/python3.10/site-packages/click/core.py\", line 1404, in invoke\n    return ctx.invoke(self.callback, **ctx.params)\n", "  File \"/usr/local/lib/python3.10/site-packages/click/core.py\", line 760, in invoke\n    return __callback(*args, **kwargs)\n", "  File \"/usr/local/lib/python3.10/site-packages/typer/main.py\", line 683, in wrapper\n    return callback(**use_params)  # type: ignore\n", "  File \"/usr/local/lib/python3.10/site-packages/mage_ai/cli/main.py\", line 124, in start\n    start_server(\n", "  File \"/usr/local/lib/python3.10/site-packages/mage_ai/server/server.py\", line 316, in start_server\n    scheduler_manager.start_scheduler()\n", "  File \"/usr/local/lib/python3.10/site-packages/mage_ai/server/scheduler_manager.py\", line 70, in start_scheduler\n    proc.start()\n", "  File \"/usr/local/lib/python3.10/multiprocessing/process.py\", line 121, in start\n    self._popen = self._Popen(self)\n", "  File \"/usr/local/lib/python3.10/multiprocessing/context.py\", line 224, in _Popen\n    return _default_context.get_context().Process._Popen(process_obj)\n", "  File \"/usr/local/lib/python3.10/multiprocessing/context.py\", line 281, in _Popen\n    return Popen(process_obj)\n", "  File \"/usr/local/lib/python3.10/multiprocessing/popen_fork.py\", line 19, in __init__\n    self._launch(process_obj)\n", "  File \"/usr/local/lib/python3.10/multiprocessing/popen_fork.py\", line 71, in _launch\n    code = process_obj._bootstrap(parent_sentinel=child_r)\n", "  File \"/usr/local/lib/python3.10/multiprocessing/process.py\", line 314, in _bootstrap\n    self.run()\n", "  File \"/usr/local/lib/python3.10/multiprocessing/process.py\", line 108, in run\n    self._target(*self._args, **self._kwargs)\n", "  File \"/usr/local/lib/python3.10/site-packages/mage_ai/orchestration/db/process.py\", line 15, in start_session_and_run\n    results = target(*args)\n", "  File \"/usr/local/lib/python3.10/site-packages/mage_ai/server/scheduler_manager.py\", line 33, in run_scheduler\n    LoopTimeTrigger().start()\n", "  File \"/usr/local/lib/python3.10/site-packages/mage_ai/orchestration/triggers/loop_time_trigger.py\", line 9, in start\n    self.run()\n", "  File \"/usr/local/lib/python3.10/site-packages/mage_ai/orchestration/triggers/time_trigger.py\", line 10, in run\n    schedule_all()\n", "  File \"/usr/local/lib/python3.10/site-packages/mage_ai/orchestration/pipeline_scheduler.py\", line 1146, in schedule_all\n    PipelineScheduler(r).schedule()\n", "  File \"/usr/local/lib/python3.10/site-packages/mage_ai/orchestration/pipeline_scheduler.py\", line 194, in schedule\n    self.__schedule_blocks(block_runs)\n", "  File \"/usr/local/lib/python3.10/site-packages/mage_ai/orchestration/pipeline_scheduler.py\", line 432, in __schedule_blocks\n    job_manager.add_job(\n", "  File \"/usr/local/lib/python3.10/site-packages/mage_ai/orchestration/job_manager.py\", line 26, in add_job\n    self.queue.enqueue(job_id, target, *args, **kwargs)\n", "  File \"/usr/local/lib/python3.10/site-packages/mage_ai/orchestration/queue/process_queue.py\", line 47, in enqueue\n    self.start_worker_pool()\n", "  File \"/usr/local/lib/python3.10/site-packages/mage_ai/orchestration/queue/process_queue.py\", line 73, in start_worker_pool\n    self.worker_pool_proc.start()\n", "  File \"/usr/local/lib/python3.10/multiprocessing/process.py\", line 121, in start\n    self._popen = self._Popen(self)\n", "  File \"/usr/local/lib/python3.10/multiprocessing/context.py\", line 224, in _Popen\n    return _default_context.get_context().Process._Popen(process_obj)\n", "  File \"/usr/local/lib/python3.10/multiprocessing/context.py\", line 281, in _Popen\n    return Popen(process_obj)\n", "  File \"/usr/local/lib/python3.10/multiprocessing/popen_fork.py\", line 19, in __init__\n    self._launch(process_obj)\n", "  File \"/usr/local/lib/python3.10/multiprocessing/popen_fork.py\", line 71, in _launch\n    code = process_obj._bootstrap(parent_sentinel=child_r)\n", "  File \"/usr/local/lib/python3.10/multiprocessing/process.py\", line 314, in _bootstrap\n    self.run()\n", "  File \"/usr/local/lib/python3.10/multiprocessing/process.py\", line 108, in run\n    self._target(*self._args, **self._kwargs)\n", "  File \"/usr/local/lib/python3.10/site-packages/mage_ai/orchestration/queue/process_queue.py\", line 123, in poll_job_and_execute\n    worker.start()\n", "  File \"/usr/local/lib/python3.10/multiprocessing/process.py\", line 121, in start\n    self._popen = self._Popen(self)\n", "  File \"/usr/local/lib/python3.10/multiprocessing/context.py\", line 224, in _Popen\n    return _default_context.get_context().Process._Popen(process_obj)\n", "  File \"/usr/local/lib/python3.10/multiprocessing/context.py\", line 281, in _Popen\n    return Popen(process_obj)\n", "  File \"/usr/local/lib/python3.10/multiprocessing/popen_fork.py\", line 19, in __init__\n    self._launch(process_obj)\n", "  File \"/usr/local/lib/python3.10/multiprocessing/popen_fork.py\", line 71, in _launch\n    code = process_obj._bootstrap(parent_sentinel=child_r)\n", "  File \"/usr/local/lib/python3.10/multiprocessing/process.py\", line 314, in _bootstrap\n    self.run()\n", "  File \"/usr/local/lib/python3.10/site-packages/mage_ai/orchestration/queue/process_queue.py\", line 103, in run\n    start_session_and_run(args[1], *args[2], **args[3])\n", "  File \"/usr/local/lib/python3.10/site-packages/mage_ai/orchestration/db/process.py\", line 15, in start_session_and_run\n    results = target(*args)\n", "  File \"/usr/local/lib/python3.10/site-packages/mage_ai/orchestration/pipeline_scheduler.py\", line 860, in run_block\n    return ExecutorFactory.get_block_executor(\n", "  File \"/usr/local/lib/python3.10/site-packages/mage_ai/data_preparation/executors/block_executor.py\", line 102, in execute\n    self.logger.exception(\n", "  File \"/usr/local/lib/python3.10/site-packages/mage_ai/data_preparation/logging/logger.py\", line 26, in exception\n    self.__send_message('exception', message, **kwargs)\n", "  File \"/usr/local/lib/python3.10/site-packages/mage_ai/data_preparation/logging/logger.py\", line 55, in __send_message\n    data['error_stack'] = traceback.format_stack(),\n"]], "error_stacktrace": ["('Connection aborted.', RemoteDisconnected('Remote end closed connection without response'))"]}
Traceback (most recent call last):
  File "/usr/local/lib/python3.10/site-packages/urllib3/connectionpool.py", line 714, in urlopen
    httplib_response = self._make_request(
  File "/usr/local/lib/python3.10/site-packages/urllib3/connectionpool.py", line 466, in _make_request
    six.raise_from(e, None)
  File "<string>", line 3, in raise_from
  File "/usr/local/lib/python3.10/site-packages/urllib3/connectionpool.py", line 461, in _make_request
    httplib_response = conn.getresponse()
  File "/usr/local/lib/python3.10/http/client.py", line 1375, in getresponse
    response.begin()
  File "/usr/local/lib/python3.10/http/client.py", line 318, in begin
    version, status, reason = self._read_status()
  File "/usr/local/lib/python3.10/http/client.py", line 287, in _read_status
    raise RemoteDisconnected("Remote end closed connection without"
http.client.RemoteDisconnected: Remote end closed connection without response

During handling of the above exception, another exception occurred:

Traceback (most recent call last):
  File "/usr/local/lib/python3.10/site-packages/requests/adapters.py", line 440, in send
    resp = conn.urlopen(
  File "/usr/local/lib/python3.10/site-packages/urllib3/connectionpool.py", line 798, in urlopen
    retries = retries.increment(
  File "/usr/local/lib/python3.10/site-packages/urllib3/util/retry.py", line 550, in increment
    raise six.reraise(type(error), error, _stacktrace)
  File "/usr/local/lib/python3.10/site-packages/urllib3/packages/six.py", line 769, in reraise
    raise value.with_traceback(tb)
  File "/usr/local/lib/python3.10/site-packages/urllib3/connectionpool.py", line 714, in urlopen
    httplib_response = self._make_request(
  File "/usr/local/lib/python3.10/site-packages/urllib3/connectionpool.py", line 466, in _make_request
    six.raise_from(e, None)
  File "<string>", line 3, in raise_from
  File "/usr/local/lib/python3.10/site-packages/urllib3/connectionpool.py", line 461, in _make_request
    httplib_response = conn.getresponse()
  File "/usr/local/lib/python3.10/http/client.py", line 1375, in getresponse
    response.begin()
  File "/usr/local/lib/python3.10/http/client.py", line 318, in begin
    version, status, reason = self._read_status()
  File "/usr/local/lib/python3.10/http/client.py", line 287, in _read_status
    raise RemoteDisconnected("Remote end closed connection without"
urllib3.exceptions.ProtocolError: ('Connection aborted.', RemoteDisconnected('Remote end closed connection without response'))

During handling of the above exception, another exception occurred:

Traceback (most recent call last):
  File "/usr/local/lib/python3.10/site-packages/mage_ai/data_preparation/executors/block_executor.py", line 100, in execute
    result = __execute_with_retry()
  File "/usr/local/lib/python3.10/site-packages/mage_ai/shared/retry.py", line 50, in retry_func
    raise e
  File "/usr/local/lib/python3.10/site-packages/mage_ai/shared/retry.py", line 34, in retry_func
    return func(*args, **kwargs)
  File "/usr/local/lib/python3.10/site-packages/mage_ai/data_preparation/executors/block_executor.py", line 84, in __execute_with_retry
    return self._execute(
  File "/usr/local/lib/python3.10/site-packages/mage_ai/data_preparation/executors/block_executor.py", line 175, in _execute
    result = self.block.execute_sync(
  File "/usr/local/lib/python3.10/site-packages/mage_ai/data_preparation/models/block/__init__.py", line 801, in execute_sync
    raise err
  File "/usr/local/lib/python3.10/site-packages/mage_ai/data_preparation/models/block/__init__.py", line 740, in execute_sync
    output = self.execute_block(
  File "/usr/local/lib/python3.10/site-packages/mage_ai/data_preparation/models/block/__init__.py", line 974, in execute_block
    outputs = self._execute_block(
  File "/usr/local/lib/python3.10/site-packages/mage_ai/data_preparation/models/block/__init__.py", line 1049, in _execute_block
    outputs = self.execute_block_function(
  File "/usr/local/lib/python3.10/site-packages/mage_ai/data_preparation/models/block/__init__.py", line 1075, in execute_block_function
    output = block_function(*input_vars, **global_vars)
  File "<string>", line 28, in export_data_to_google_cloud_storage
  File "/usr/local/lib/python3.10/site-packages/mage_ai/io/google_cloud_storage.py", line 131, in export
    blob.upload_from_string(buffer.read())
  File "/usr/local/lib/python3.10/site-packages/google/cloud/storage/blob.py", line 2840, in upload_from_string
    self.upload_from_file(
  File "/usr/local/lib/python3.10/site-packages/google/cloud/storage/blob.py", line 2567, in upload_from_file
    created_json = self._do_upload(
  File "/usr/local/lib/python3.10/site-packages/google/cloud/storage/blob.py", line 2368, in _do_upload
    response = self._do_multipart_upload(
  File "/usr/local/lib/python3.10/site-packages/google/cloud/storage/blob.py", line 1903, in _do_multipart_upload
    response = upload.transmit(
  File "/usr/local/lib/python3.10/site-packages/google/resumable_media/requests/upload.py", line 153, in transmit
    return _request_helpers.wait_and_retry(
  File "/usr/local/lib/python3.10/site-packages/google/resumable_media/requests/_request_helpers.py", line 178, in wait_and_retry
    raise error
  File "/usr/local/lib/python3.10/site-packages/google/resumable_media/requests/_request_helpers.py", line 155, in wait_and_retry
    response = func()
  File "/usr/local/lib/python3.10/site-packages/google/resumable_media/requests/upload.py", line 145, in retriable_request
    result = transport.request(
  File "/usr/local/lib/python3.10/site-packages/google/auth/transport/requests.py", line 549, in request
    response = super(AuthorizedSession, self).request(
  File "/usr/local/lib/python3.10/site-packages/requests/sessions.py", line 529, in request
    resp = self.send(prep, **send_kwargs)
  File "/usr/local/lib/python3.10/site-packages/requests/sessions.py", line 645, in send
    r = adapter.send(request, **kwargs)
  File "/usr/local/lib/python3.10/site-packages/requests/adapters.py", line 501, in send
    raise ConnectionError(err, request=request)
requests.exceptions.ConnectionError: ('Connection aborted.', RemoteDisconnected('Remote end closed connection without response'))
